<?xml version="1.0" ?>
<!-- =================================================================================== -->
<!-- |    This document was autogenerated by xacro from mybot.xacro                    | -->
<!-- |    EDITING THIS FILE BY HAND IS NOT RECOMMENDED                                 | -->
<!-- =================================================================================== -->
<robot name="mybot" xmlns:xacro="http://www.ros.org/wiki/xacro">
  <!-- Put here the robot description -->
  <gazebo reference="chassis">
    <material>Gazebo/Orange</material>
  </gazebo>
  <gazebo>
    <plugin filename="libgazebo_ros_control.so" name="gazebo_ros_control">
      <robotNamespace>/mybot</robotNamespace>
    </plugin>
  </gazebo>
  <gazebo>
    <plugin filename="libgazebo_ros_skid_steer_drive.so" name="skid_steer_drive_controller">
      <updateRate>100.0</updateRate>
      <robotNamespace>/</robotNamespace>
      <leftFrontJoint>front_left_wheel_joint</leftFrontJoint>
      <rightFrontJoint>front_right_wheel_joint</rightFrontJoint>
      <leftRearJoint>back_left_wheel_joint</leftRearJoint>
      <rightRearJoint>back_right_wheel_joint</rightRearJoint>
      <wheelSeparation>0.4</wheelSeparation>
      <wheelDiameter>0.215</wheelDiameter>
      <robotBaseFrame>base_link</robotBaseFrame>
      <torque>20</torque>
      <topicName>cmd_vel</topicName>
      <broadcastTF>false</broadcastTF>
    </plugin>
  </gazebo>
  <gazebo reference="laser">
    <sensor name="laser" type="ray">
      <pose>0 0 0 0 0 0</pose>
      <visualize>true</visualize>
      <update_rate>40</update_rate>
      <ray>
        <scan>
          <horizontal>
            <samples>220</samples>
            <resolution>1</resolution>
            <min_angle>-0.5</min_angle>
            <max_angle>0.5</max_angle>
          </horizontal>
        </scan>
        <range>
          <min>0.10</min>
          <max>3.0</max>
          <resolution>0.01</resolution>
        </range>
        <noise>
          <type>gaussian</type>
          <!-- Noise parameters based on published spec for Hokuyo laser
	      achieving "+-30mm" accuracy at range < 10m.  A mean of 0.0m and
	      stddev of 0.01m will put 99.7% of samples within 0.03m of the true reading. -->
          <mean>0.0</mean>
          <stddev>0.01</stddev>
        </noise>
      </ray>
      <plugin filename="libgazebo_ros_laser.so" name="gazebo_ros_head_hokuyo_controller">
        <topicName>/laser/scan</topicName>
        <frameName>laser</frameName>
      </plugin>
    </sensor>
  </gazebo>
  <material name="black">
    <color rgba="0.0 0.0 0.0 1.0"/>
  </material>
  <material name="blue">
    <color rgba="0.0 0.0 0.8 1.0"/>
  </material>
  <material name="green">
    <color rgba="0.0 0.8 0.0 1.0"/>
  </material>
  <material name="grey">
    <color rgba="0.2 0.2 0.2 1.0"/>
  </material>
  <material name="orange">
    <color rgba="1.0 0.423529411765 0.0392156862745 1.0"/>
  </material>
  <material name="brown">
    <color rgba="0.870588235294 0.811764705882 0.764705882353 1.0"/>
  </material>
  <material name="red">
    <color rgba="0.8 0.0 0.0 1.0"/>
  </material>
  <material name="white">
    <color rgba="1.0 1.0 1.0 1.0"/>
  </material>
  <link name="base_link"/>
  <joint name="base_joint" type="fixed">
    <parent link="base_link"/>
    <child link="chassis"/>
    <origin rpy="0 0 0" xyz="-0.2 0 0"/>
    <axis rpy="0 0 0" xyz="1 0 0"/>
  </joint>
  <link name="chassis">
    <collision>
      <origin rpy="0 0 0" xyz="0 0 0.1"/>
      <geometry>
        <box size="0.4 0.2 0.1"/>
      </geometry>
    </collision>
    <visual>
      <origin rpy="0 0 0" xyz="0 0 0.1"/>
      <geometry>
        <box size="0.4 0.2 0.1"/>
      </geometry>
      <material name="orange"/>
    </visual>
    <inertial>
      <origin rpy="0 0 0" xyz="0 0 0.1"/>
      <mass value="50"/>
      <inertia ixx="0.208333333333" ixy="0" ixz="0" iyy="0.708333333333" iyz="0" izz="0.708333333333"/>
    </inertial>
  </link>
  <link name="front_left_wheel">
    <collision>
      <origin rpy="0 1.57079632679 1.57079632679" xyz="0 0 0"/>
      <geometry>
        <cylinder length="0.02" radius="0.05"/>
      </geometry>
    </collision>
    <visual>
      <origin rpy="0 1.57079632679 1.57079632679" xyz="0 0 0"/>
      <geometry>
        <cylinder length="0.02" radius="0.05"/>
      </geometry>
      <material name="black"/>
    </visual>
    <inertial>
      <origin rpy="0 1.57079632679 1.57079632679" xyz="0 0 0"/>
      <mass value="5"/>
      <inertia ixx="0.00329166666667" ixy="0" ixz="0" iyy="0.00329166666667" iyz="0" izz="0.00625"/>
    </inertial>
  </link>
  <gazebo reference="front_left_wheel">
    <!--    
    <mu1 value="1.0"/>
    <mu2 value="1.0"/>
    <kp  value="10000000.0" />
    <kd  value="1.0" />
    <fdir1 value="1 0 0"/>
    -->
    <material>Gazebo/Black</material>
  </gazebo>
  <joint name="front_left_wheel_joint" type="continuous">
    <parent link="chassis"/>
    <child link="front_left_wheel"/>
    <!--    <origin xyz="${tX*chassisLength/2} ${tY*wheelWidth/2+tY*chassisWidth/2} ${wheelRadius}" rpy="0 0 0" /> -->
    <origin rpy="0 0 0" xyz="0.12 0.1 0.05"/>
    <axis rpy="0 0 0" xyz="0 1 0"/>
    <limit effort="100" velocity="100"/>
    <joint_properties damping="0.0" friction="0.0"/>
  </joint>
  <transmission name="front_left_trans">
    <type>transmission_interface/SimpleTransmission</type>
    <joint name="front_left_wheel_joint">
      <hardwareInterface>EffortJointInterface</hardwareInterface>
    </joint>
    <actuator name="front_leftMotor">
      <hardwareInterface>EffortJointInterface</hardwareInterface>
      <mechanicalReduction>10</mechanicalReduction>
    </actuator>
  </transmission>
  <link name="front_right_wheel">
    <collision>
      <origin rpy="0 1.57079632679 1.57079632679" xyz="0 0 0"/>
      <geometry>
        <cylinder length="0.02" radius="0.05"/>
      </geometry>
    </collision>
    <visual>
      <origin rpy="0 1.57079632679 1.57079632679" xyz="0 0 0"/>
      <geometry>
        <cylinder length="0.02" radius="0.05"/>
      </geometry>
      <material name="black"/>
    </visual>
    <inertial>
      <origin rpy="0 1.57079632679 1.57079632679" xyz="0 0 0"/>
      <mass value="5"/>
      <inertia ixx="0.00329166666667" ixy="0" ixz="0" iyy="0.00329166666667" iyz="0" izz="0.00625"/>
    </inertial>
  </link>
  <gazebo reference="front_right_wheel">
    <!--    
    <mu1 value="1.0"/>
    <mu2 value="1.0"/>
    <kp  value="10000000.0" />
    <kd  value="1.0" />
    <fdir1 value="1 0 0"/>
    -->
    <material>Gazebo/Black</material>
  </gazebo>
  <joint name="front_right_wheel_joint" type="continuous">
    <parent link="chassis"/>
    <child link="front_right_wheel"/>
    <!--    <origin xyz="${tX*chassisLength/2} ${tY*wheelWidth/2+tY*chassisWidth/2} ${wheelRadius}" rpy="0 0 0" /> -->
    <origin rpy="0 0 0" xyz="0.12 -0.1 0.05"/>
    <axis rpy="0 0 0" xyz="0 1 0"/>
    <limit effort="100" velocity="100"/>
    <joint_properties damping="0.0" friction="0.0"/>
  </joint>
  <transmission name="front_right_trans">
    <type>transmission_interface/SimpleTransmission</type>
    <joint name="front_right_wheel_joint">
      <hardwareInterface>EffortJointInterface</hardwareInterface>
    </joint>
    <actuator name="front_rightMotor">
      <hardwareInterface>EffortJointInterface</hardwareInterface>
      <mechanicalReduction>10</mechanicalReduction>
    </actuator>
  </transmission>
  <link name="back_left_wheel">
    <collision>
      <origin rpy="0 1.57079632679 1.57079632679" xyz="0 0 0"/>
      <geometry>
        <cylinder length="0.02" radius="0.05"/>
      </geometry>
    </collision>
    <visual>
      <origin rpy="0 1.57079632679 1.57079632679" xyz="0 0 0"/>
      <geometry>
        <cylinder length="0.02" radius="0.05"/>
      </geometry>
      <material name="black"/>
    </visual>
    <inertial>
      <origin rpy="0 1.57079632679 1.57079632679" xyz="0 0 0"/>
      <mass value="5"/>
      <inertia ixx="0.00329166666667" ixy="0" ixz="0" iyy="0.00329166666667" iyz="0" izz="0.00625"/>
    </inertial>
  </link>
  <gazebo reference="back_left_wheel">
    <!--    
    <mu1 value="1.0"/>
    <mu2 value="1.0"/>
    <kp  value="10000000.0" />
    <kd  value="1.0" />
    <fdir1 value="1 0 0"/>
    -->
    <material>Gazebo/Black</material>
  </gazebo>
  <joint name="back_left_wheel_joint" type="continuous">
    <parent link="chassis"/>
    <child link="back_left_wheel"/>
    <!--    <origin xyz="${tX*chassisLength/2} ${tY*wheelWidth/2+tY*chassisWidth/2} ${wheelRadius}" rpy="0 0 0" /> -->
    <origin rpy="0 0 0" xyz="-0.12 0.1 0.05"/>
    <axis rpy="0 0 0" xyz="0 1 0"/>
    <limit effort="100" velocity="100"/>
    <joint_properties damping="0.0" friction="0.0"/>
  </joint>
  <transmission name="back_left_trans">
    <type>transmission_interface/SimpleTransmission</type>
    <joint name="back_left_wheel_joint">
      <hardwareInterface>EffortJointInterface</hardwareInterface>
    </joint>
    <actuator name="back_leftMotor">
      <hardwareInterface>EffortJointInterface</hardwareInterface>
      <mechanicalReduction>10</mechanicalReduction>
    </actuator>
  </transmission>
  <link name="back_right_wheel">
    <collision>
      <origin rpy="0 1.57079632679 1.57079632679" xyz="0 0 0"/>
      <geometry>
        <cylinder length="0.02" radius="0.05"/>
      </geometry>
    </collision>
    <visual>
      <origin rpy="0 1.57079632679 1.57079632679" xyz="0 0 0"/>
      <geometry>
        <cylinder length="0.02" radius="0.05"/>
      </geometry>
      <material name="black"/>
    </visual>
    <inertial>
      <origin rpy="0 1.57079632679 1.57079632679" xyz="0 0 0"/>
      <mass value="5"/>
      <inertia ixx="0.00329166666667" ixy="0" ixz="0" iyy="0.00329166666667" iyz="0" izz="0.00625"/>
    </inertial>
  </link>
  <gazebo reference="back_right_wheel">
    <!--    
    <mu1 value="1.0"/>
    <mu2 value="1.0"/>
    <kp  value="10000000.0" />
    <kd  value="1.0" />
    <fdir1 value="1 0 0"/>
    -->
    <material>Gazebo/Black</material>
  </gazebo>
  <joint name="back_right_wheel_joint" type="continuous">
    <parent link="chassis"/>
    <child link="back_right_wheel"/>
    <!--    <origin xyz="${tX*chassisLength/2} ${tY*wheelWidth/2+tY*chassisWidth/2} ${wheelRadius}" rpy="0 0 0" /> -->
    <origin rpy="0 0 0" xyz="-0.12 -0.1 0.05"/>
    <axis rpy="0 0 0" xyz="0 1 0"/>
    <limit effort="100" velocity="100"/>
    <joint_properties damping="0.0" friction="0.0"/>
  </joint>
  <transmission name="back_right_trans">
    <type>transmission_interface/SimpleTransmission</type>
    <joint name="back_right_wheel_joint">
      <hardwareInterface>EffortJointInterface</hardwareInterface>
    </joint>
    <actuator name="back_rightMotor">
      <hardwareInterface>EffortJointInterface</hardwareInterface>
      <mechanicalReduction>10</mechanicalReduction>
    </actuator>
  </transmission>
  <joint name="laser_joint" type="fixed">
    <axis xyz="0 1 0"/>
    <origin rpy="0 0 0" xyz="0 0 0.15"/>
    <parent link="base_link"/>
    <child link="laser"/>
  </joint>
  <!-- Hokuyo Laser -->
  <link name="laser">
    <collision>
      <origin rpy="0 0 0" xyz="0 0 0"/>
      <geometry>
        <box size="0.1 0.1 0.1"/>
      </geometry>
    </collision>
    <visual>
      <origin rpy="0 0 0" xyz="0 0 0"/>
      <geometry>
        <mesh filename="package://mybot_description/meshes/hokuyo.dae"/>
      </geometry>
    </visual>
    <inertial>
      <mass value="1e-5"/>
      <origin rpy="0 0 0" xyz="0 0 0"/>
      <inertia ixx="1e-6" ixy="0" ixz="0" iyy="1e-6" iyz="0" izz="1e-6"/>
    </inertial>
  </link>
</robot>

